<?xml version="1.0" ?>
<!-- =================================================================================== -->
<!-- |    This document was autogenerated by xacro from kbot.urdf.xacro                | -->
<!-- |    EDITING THIS FILE BY HAND IS NOT RECOMMENDED                                 | -->
<!-- =================================================================================== -->
<robot name="kbot">
  <material name="aluminum">
    <color rgba="0.5 0.5 0.5 1"/>
  </material>
  <material name="plastic">
    <color rgba="0.1 0.1 0.1 1"/>
  </material>
  <link name="world"/>
  <ros2_control name="KortexMultiInterfaceHardware" type="system">
    <hardware>
      <plugin>topic_based_ros2_control/TopicBasedSystem</plugin>
      <param name="joint_commands_topic">/isaac_joint_commands</param>
      <param name="joint_states_topic">/isaac_joint_states</param>
    </hardware>
    <joint name="joint_1">
      <command_interface name="position">
        <param name="min">{-2*pi}</param>
        <param name="max">{2*pi}</param>
      </command_interface>
      <command_interface name="velocity">
        <param name="min">-3.15</param>
        <param name="max">3.15</param>
      </command_interface>
      <state_interface name="position">
        <param name="initial_value">0.0</param>
      </state_interface>
      <state_interface name="velocity"/>
      <state_interface name="effort"/>
    </joint>
    <joint name="joint_2">
      <command_interface name="position">
        <param name="min">-2.41</param>
        <param name="max">2.41</param>
      </command_interface>
      <command_interface name="velocity">
        <param name="min">-3.15</param>
        <param name="max">3.15</param>
      </command_interface>
      <state_interface name="position">
        <param name="initial_value">0.0</param>
      </state_interface>
      <state_interface name="velocity"/>
      <state_interface name="effort"/>
    </joint>
    <joint name="joint_3">
      <command_interface name="position">
        <param name="min">{-2*pi}</param>
        <param name="max">{2*pi}</param>
      </command_interface>
      <command_interface name="velocity">
        <param name="min">-3.15</param>
        <param name="max">3.15</param>
      </command_interface>
      <state_interface name="position">
        <param name="initial_value">0.0</param>
      </state_interface>
      <state_interface name="velocity"/>
      <state_interface name="effort"/>
    </joint>
    <joint name="joint_4">
      <command_interface name="position">
        <param name="min">-2.66</param>
        <param name="max">2.66</param>
      </command_interface>
      <command_interface name="velocity">
        <param name="min">-3.2</param>
        <param name="max">3.2</param>
      </command_interface>
      <state_interface name="position">
        <param name="initial_value">0.0</param>
      </state_interface>
      <state_interface name="velocity"/>
      <state_interface name="effort"/>
    </joint>
    <joint name="joint_5">
      <command_interface name="position">
        <param name="min">{-2*pi}</param>
        <param name="max">{2*pi}</param>
      </command_interface>
      <command_interface name="velocity">
        <param name="min">-3.2</param>
        <param name="max">3.2</param>
      </command_interface>
      <state_interface name="position">
        <param name="initial_value">0.0</param>
      </state_interface>
      <state_interface name="velocity"/>
      <state_interface name="effort"/>
    </joint>
    <joint name="joint_6">
      <command_interface name="position">
        <param name="min">-2.23</param>
        <param name="max">2.23</param>
      </command_interface>
      <command_interface name="velocity">
        <param name="min">-3.2</param>
        <param name="max">3.2</param>
      </command_interface>
      <state_interface name="position">
        <param name="initial_value">0.0</param>
      </state_interface>
      <state_interface name="velocity"/>
      <state_interface name="effort"/>
    </joint>
    <joint name="joint_7">
      <command_interface name="position">
        <param name="min">{-2*pi}</param>
        <param name="max">{2*pi}</param>
      </command_interface>
      <command_interface name="velocity">
        <param name="min">-3.2</param>
        <param name="max">3.2</param>
      </command_interface>
      <state_interface name="position">
        <param name="initial_value">0.0</param>
      </state_interface>
      <state_interface name="velocity"/>
      <state_interface name="effort"/>
    </joint>
  </ros2_control>
  <joint name="base_joint" type="fixed">
    <origin rpy="0 0 0" xyz="0 0 0"/>
    <parent link="world"/>
    <child link="base_link"/>
  </joint>
  <link name="base_link">
    <inertial>
      <origin rpy="0 0 0" xyz="-0.000648 -0.000166 0.084487"/>
      <mass value="1.697"/>
      <inertia ixx="0.004622" ixy="9E-06" ixz="6E-05" iyy="0.004495" iyz="9E-06" izz="0.002079"/>
    </inertial>
    <visual>
      <origin rpy="0 0 0" xyz="0 0 0"/>
      <geometry>
        <mesh filename="package://kortex_description/arms/gen3/7dof/meshes/base_link.dae"/>
      </geometry>
      <material name="">
        <color rgba="0.75294 0.75294 0.75294 1"/>
      </material>
    </visual>
    <collision>
      <origin rpy="0 0 0" xyz="0 0 0"/>
      <geometry>
        <mesh filename="package://kortex_description/arms/gen3/7dof/meshes/base_link.dae"/>
      </geometry>
    </collision>
  </link>
  <link name="shoulder_link">
    <inertial>
      <origin rpy="0 0 0" xyz="-2.3E-05 -0.010364 -0.07336"/>
      <mass value="1.3773"/>
      <inertia ixx="0.00457" ixy="1E-06" ixz="2E-06" iyy="0.004831" iyz="0.000448" izz="0.001409"/>
    </inertial>
    <visual>
      <origin rpy="0 0 0" xyz="0 0 0"/>
      <geometry>
        <mesh filename="package://kortex_description/arms/gen3/7dof/meshes/shoulder_link.dae"/>
      </geometry>
      <material name="">
        <color rgba="0.75294 0.75294 0.75294 1"/>
      </material>
    </visual>
    <collision>
      <origin rpy="0 0 0" xyz="0 0 0"/>
      <geometry>
        <mesh filename="package://kortex_description/arms/gen3/7dof/meshes/shoulder_link.dae"/>
      </geometry>
    </collision>
  </link>
  <joint name="joint_1" type="continuous">
    <origin rpy="3.1416 2.7629E-18 -4.9305E-36" xyz="0 0 0.15643"/>
    <parent link="base_link"/>
    <child link="shoulder_link"/>
    <axis xyz="0 0 1"/>
    <limit effort="39" velocity="1.3963"/>
  </joint>
  <link name="half_arm_1_link">
    <inertial>
      <origin rpy="0 0 0" xyz="-4.4E-05 -0.09958 -0.013278"/>
      <mass value="1.1636"/>
      <inertia ixx="0.011088" ixy="5E-06" ixz="0" iyy="0.001072" iyz="-0.000691" izz="0.011255"/>
    </inertial>
    <visual>
      <origin rpy="0 0 0" xyz="0 0 0"/>
      <geometry>
        <mesh filename="package://kortex_description/arms/gen3/7dof/meshes/half_arm_1_link.dae"/>
      </geometry>
      <material name="">
        <color rgba="0.75294 0.75294 0.75294 1"/>
      </material>
    </visual>
    <collision>
      <origin rpy="0 0 0" xyz="0 0 0"/>
      <geometry>
        <mesh filename="package://kortex_description/arms/gen3/7dof/meshes/half_arm_1_link.dae"/>
      </geometry>
    </collision>
  </link>
  <joint name="joint_2" type="revolute">
    <origin rpy="1.5708 2.1343E-17 -1.1102E-16" xyz="0 0.005375 -0.12838"/>
    <parent link="shoulder_link"/>
    <child link="half_arm_1_link"/>
    <axis xyz="0 0 1"/>
    <limit effort="39" lower="-2.41" upper="2.41" velocity="1.3963"/>
  </joint>
  <link name="half_arm_2_link">
    <inertial>
      <origin rpy="0 0 0" xyz="-4.4E-05 -0.006641 -0.117892"/>
      <mass value="1.1636"/>
      <inertia ixx="0.010932" ixy="0" ixz="-7E-06" iyy="0.011127" iyz="0.000606" izz="0.001043"/>
    </inertial>
    <visual>
      <origin rpy="0 0 0" xyz="0 0 0"/>
      <geometry>
        <mesh filename="package://kortex_description/arms/gen3/7dof/meshes/half_arm_2_link.dae"/>
      </geometry>
      <material name="">
        <color rgba="0.75294 0.75294 0.75294 1"/>
      </material>
    </visual>
    <collision>
      <origin rpy="0 0 0" xyz="0 0 0"/>
      <geometry>
        <mesh filename="package://kortex_description/arms/gen3/7dof/meshes/half_arm_2_link.dae"/>
      </geometry>
    </collision>
  </link>
  <joint name="joint_3" type="continuous">
    <origin rpy="-1.5708 1.2326E-32 -2.9122E-16" xyz="0 -0.21038 -0.006375"/>
    <parent link="half_arm_1_link"/>
    <child link="half_arm_2_link"/>
    <axis xyz="0 0 1"/>
    <limit effort="39" velocity="1.3963"/>
  </joint>
  <link name="forearm_link">
    <inertial>
      <origin rpy="0 0 0" xyz="-1.8E-05 -0.075478 -0.015006"/>
      <mass value="0.9302"/>
      <inertia ixx="0.008147" ixy="-1E-06" ixz="0" iyy="0.000631" iyz="-0.0005" izz="0.008316"/>
    </inertial>
    <visual>
      <origin rpy="0 0 0" xyz="0 0 0"/>
      <geometry>
        <mesh filename="package://kortex_description/arms/gen3/7dof/meshes/forearm_link.dae"/>
      </geometry>
      <material name="">
        <color rgba="0.75294 0.75294 0.75294 1"/>
      </material>
    </visual>
    <collision>
      <origin rpy="0 0 0" xyz="0 0 0"/>
      <geometry>
        <mesh filename="package://kortex_description/arms/gen3/7dof/meshes/forearm_link.dae"/>
      </geometry>
    </collision>
  </link>
  <joint name="joint_4" type="revolute">
    <origin rpy="1.5708 -6.6954E-17 -1.6653E-16" xyz="0 0.006375 -0.21038"/>
    <parent link="half_arm_2_link"/>
    <child link="forearm_link"/>
    <axis xyz="0 0 1"/>
    <limit effort="39" lower="-2.66" upper="2.66" velocity="1.3963"/>
  </joint>
  <link name="spherical_wrist_1_link">
    <inertial>
      <origin rpy="0 0 0" xyz="1E-06 -0.009432 -0.063883"/>
      <mass value="0.6781"/>
      <inertia ixx="0.001596" ixy="0" ixz="0" iyy="0.001607" iyz="0.000256" izz="0.000399"/>
    </inertial>
    <visual>
      <origin rpy="0 0 0" xyz="0 0 0"/>
      <geometry>
        <mesh filename="package://kortex_description/arms/gen3/7dof/meshes/spherical_wrist_1_link.dae"/>
      </geometry>
      <material name="">
        <color rgba="0.75294 0.75294 0.75294 1"/>
      </material>
    </visual>
    <collision>
      <origin rpy="0 0 0" xyz="0 0 0"/>
      <geometry>
        <mesh filename="package://kortex_description/arms/gen3/7dof/meshes/spherical_wrist_1_link.dae"/>
      </geometry>
    </collision>
  </link>
  <joint name="joint_5" type="continuous">
    <origin rpy="-1.5708 2.2204E-16 -6.373E-17" xyz="0 -0.20843 -0.006375"/>
    <parent link="forearm_link"/>
    <child link="spherical_wrist_1_link"/>
    <axis xyz="0 0 1"/>
    <limit effort="9" velocity="1.2218"/>
  </joint>
  <link name="spherical_wrist_2_link">
    <inertial>
      <origin rpy="0 0 0" xyz="1E-06 -0.045483 -0.00965"/>
      <mass value="0.6781"/>
      <inertia ixx="0.001641" ixy="0" ixz="0" iyy="0.00041" iyz="-0.000278" izz="0.001641"/>
    </inertial>
    <visual>
      <origin rpy="0 0 0" xyz="0 0 0"/>
      <geometry>
        <mesh filename="package://kortex_description/arms/gen3/7dof/meshes/spherical_wrist_2_link.dae"/>
      </geometry>
      <material name="">
        <color rgba="0.75294 0.75294 0.75294 1"/>
      </material>
    </visual>
    <collision>
      <origin rpy="0 0 0" xyz="0 0 0"/>
      <geometry>
        <mesh filename="package://kortex_description/arms/gen3/7dof/meshes/spherical_wrist_2_link.dae"/>
      </geometry>
    </collision>
  </link>
  <joint name="joint_6" type="revolute">
    <origin rpy="1.5708 9.2076E-28 -8.2157E-15" xyz="0 0.00017505 -0.10593"/>
    <parent link="spherical_wrist_1_link"/>
    <child link="spherical_wrist_2_link"/>
    <axis xyz="0 0 1"/>
    <limit effort="9" lower="-2.23" upper="2.23" velocity="1.2218"/>
  </joint>
  <link name="bracelet_link">
    <inertial>
      <origin rpy="0 0 0" xyz="-9.3E-05 0.000132 -0.022905"/>
      <mass value="0.364"/>
      <inertia ixx="0.000214" ixy="0" ixz="1E-06" iyy="0.000223" iyz="-2E-06" izz="0.00024"/>
    </inertial>
    <visual>
      <origin rpy="0 0 0" xyz="0 0 0"/>
      <geometry>
        <mesh filename="package://kortex_description/arms/gen3/7dof/meshes/bracelet_no_vision_link.dae"/>
      </geometry>
      <material name="">
        <color rgba="0.75294 0.75294 0.75294 1"/>
      </material>
    </visual>
    <collision>
      <origin rpy="0 0 0" xyz="0 0 0"/>
      <geometry>
        <mesh filename="package://kortex_description/arms/gen3/7dof/meshes/bracelet_no_vision_link.dae"/>
      </geometry>
    </collision>
  </link>
  <joint name="joint_7" type="continuous">
    <origin rpy="-1.5708 -5.5511E-17 9.6396E-17" xyz="0 -0.10593 -0.00017505"/>
    <parent link="spherical_wrist_2_link"/>
    <child link="bracelet_link"/>
    <axis xyz="0 0 1"/>
    <limit effort="9" velocity="1.2218"/>
  </joint>
  <link name="end_effector_link"/>
  <joint name="end_effector" type="fixed">
    <origin rpy="3.14159265358979 1.09937075168372E-32 0" xyz="0 0 -0.0615250000000001"/>
    <parent link="bracelet_link"/>
    <child link="end_effector_link"/>
    <axis xyz="0 0 0"/>
  </joint>
  <link name="tool_frame"/>
  <joint name="tool_frame_joint" type="fixed">
    <origin rpy="0 0 0" xyz="0 0 0"/>
    <parent link="end_effector_link"/>
    <child link="tool_frame"/>
    <axis xyz="0 0 0"/>
  </joint>
  <!-- Camera Bracket -->
  <link name="wrist_camera_link_visual">
    <inertial>
      <origin rpy="0 0 0" xyz="0.000281 0.011402 -0.029798"/>
      <mass value="0.5"/>
      <inertia ixx="0.000587" ixy="3E-06" ixz="3E-06" iyy="0.000369" iyz="-0.000118" izz="0.000609"/>
    </inertial>
    <visual>
      <origin rpy="0 0 0" xyz="0 0 0"/>
      <geometry>
        <mesh filename="package://kbot_description/meshes/visual/realsense_bracket_for_gen3.dae"/>
      </geometry>
    </visual>
    <collision>
      <origin rpy="0 0 0" xyz="0 0 0"/>
      <geometry>
        <mesh filename="package://kbot_description/meshes/visual/realsense_bracket_for_gen3.dae"/>
      </geometry>
    </collision>
  </link>
  <joint name="wrist_camera_link_visual_joint" type="fixed">
    <origin rpy="0 0 0" xyz="0 0 0.0"/>
    <parent link="bracelet_link"/>
    <child link="wrist_camera_link_visual"/>
  </joint>
  <!-- Wrist Camera -->
  <link name="wrist_camera_link"/>
  <joint name="wrist_camera_joint" type="fixed">
    <parent link="bracelet_link"/>
    <child link="wrist_camera_link"/>
    <origin rpy="0 1.7444444444444447 -1.5708" xyz="0 -0.06841 -0.05044"/>
  </joint>
  <!-- camera body, with origin at bottom screw mount -->
  <joint name="wrist_mounted_camera_joint" type="fixed">
    <origin rpy="0 0 0" xyz="0 0 0"/>
    <parent link="wrist_camera_link"/>
    <child link="wrist_mounted_camera_bottom_screw_frame"/>
  </joint>
  <link name="wrist_mounted_camera_bottom_screw_frame"/>
  <joint name="wrist_mounted_camera_link_joint" type="fixed">
    <origin rpy="0 0 0" xyz="0 0.02 0.0115"/>
    <parent link="wrist_mounted_camera_bottom_screw_frame"/>
    <child link="wrist_mounted_camera_link"/>
  </joint>
  <link name="wrist_mounted_camera_link">
    <visual>
      <origin rpy="1.5707963267948966 0 1.5707963267948966" xyz="0.00987 -0.02 0"/>
      <geometry>
        <mesh filename="package://realsense2_description/meshes/d415.stl"/>
      </geometry>
      <material name="aluminum"/>
    </visual>
    <collision>
      <origin rpy="0 0 0" xyz="0 -0.02 0"/>
      <geometry>
        <box size="0.02005 0.099 0.023"/>
      </geometry>
    </collision>
    <inertial>
      <mass value="0.072"/>
      <!-- The following are not reliable values, and should not be used for modeling -->
      <origin xyz="0 0 0"/>
      <inertia ixx="0.003881243" ixy="0.0" ixz="0.0" iyy="0.000498940" iyz="0.0" izz="0.003879257"/>
    </inertial>
  </link>
  <ros2_control name="RobotiqGripperHardwareInterface" type="system">
    <!-- Plugins -->
    <hardware>
      <plugin>topic_based_ros2_control/TopicBasedSystem</plugin>
      <param name="joint_commands_topic">/isaac_joint_commands</param>
      <param name="joint_states_topic">/isaac_joint_states</param>
    </hardware>
    <!-- Joint interfaces -->
    <!-- With Ignition or Hardware, they handle mimic joints, so we only need this command interface activated -->
    <joint name="robotiq_85_left_knuckle_joint">
      <command_interface name="position"/>
      <state_interface name="position">
        <param name="initial_value">0.7929</param>
      </state_interface>
      <state_interface name="velocity"/>
    </joint>
    <joint name="robotiq_85_right_knuckle_joint">
      <param name="mimic">robotiq_85_left_knuckle_joint</param>
      <param name="multiplier">-1</param>
      <command_interface name="position"/>
      <state_interface name="position"/>
      <state_interface name="velocity"/>
    </joint>
    <joint name="robotiq_85_left_inner_knuckle_joint">
      <param name="mimic">robotiq_85_left_knuckle_joint</param>
      <param name="multiplier">1</param>
      <command_interface name="position"/>
      <state_interface name="position"/>
      <state_interface name="velocity"/>
    </joint>
    <joint name="robotiq_85_right_inner_knuckle_joint">
      <param name="mimic">robotiq_85_left_knuckle_joint</param>
      <param name="multiplier">-1</param>
      <command_interface name="position"/>
      <state_interface name="position"/>
      <state_interface name="velocity"/>
    </joint>
    <joint name="robotiq_85_left_finger_tip_joint">
      <param name="mimic">robotiq_85_left_knuckle_joint</param>
      <param name="multiplier">-1</param>
      <command_interface name="position"/>
      <state_interface name="position"/>
      <state_interface name="velocity"/>
    </joint>
    <joint name="robotiq_85_right_finger_tip_joint">
      <param name="mimic">robotiq_85_left_knuckle_joint</param>
      <param name="multiplier">1</param>
      <command_interface name="position"/>
      <state_interface name="position"/>
      <state_interface name="velocity"/>
    </joint>
  </ros2_control>
  <link name="robotiq_85_base_link">
    <visual>
      <geometry>
        <mesh filename="package://robotiq_description/meshes/visual/robotiq_base.dae"/>
      </geometry>
    </visual>
    <collision>
      <geometry>
        <mesh filename="package://robotiq_description/meshes/collision/robotiq_base.stl"/>
      </geometry>
    </collision>
    <inertial>
      <origin rpy="0 0 0" xyz="0.0 2.274e-05 0.03232288"/>
      <mass value="6.6320197e-01"/>
      <inertia ixx="5.1617816e-04" ixy="2.936e-8" ixz="0.0" iyy="5.8802208e-04" iyz="-3.2296e-7" izz="3.9462776e-04"/>
    </inertial>
  </link>
  <link name="robotiq_85_left_knuckle_link">
    <visual>
      <geometry>
        <mesh filename="package://robotiq_description/meshes/visual/left_knuckle.dae"/>
      </geometry>
    </visual>
    <collision>
      <geometry>
        <mesh filename="package://robotiq_description/meshes/collision/left_knuckle.stl"/>
      </geometry>
    </collision>
    <inertial>
      <origin rpy="0 0 0" xyz="0.01213197 0.0002 -0.00058647"/>
      <mass value="1.384773208e-02"/>
      <inertia ixx="3.5232e-7" ixy="0.0" ixz="1.1744e-7" iyy="2.31944e-6" iyz="0" izz="2.23136e-6"/>
    </inertial>
  </link>
  <link name="robotiq_85_right_knuckle_link">
    <visual>
      <geometry>
        <mesh filename="package://robotiq_description/meshes/visual/right_knuckle.dae"/>
      </geometry>
    </visual>
    <collision>
      <geometry>
        <mesh filename="package://robotiq_description/meshes/collision/right_knuckle.stl"/>
      </geometry>
    </collision>
    <inertial>
      <origin rpy="0 0 0" xyz="-0.01213197 0.0002 -0.00058647"/>
      <mass value="1.384773208e-02"/>
      <inertia ixx="3.5232e-7" ixy="0.0" ixz="-1.1744e-7" iyy="2.31944e-6" iyz="0.0" izz="2.23136e-6"/>
    </inertial>
  </link>
  <link name="robotiq_85_left_finger_link">
    <visual>
      <geometry>
        <mesh filename="package://robotiq_description/meshes/visual/left_finger.dae"/>
      </geometry>
    </visual>
    <collision>
      <geometry>
        <mesh filename="package://robotiq_description/meshes/collision/left_finger.stl"/>
      </geometry>
    </collision>
    <inertial>
      <origin rpy="0 0 0" xyz="0.00346899 -0.00079447 0.01867121"/>
      <mass value="4.260376752e-02"/>
      <inertia ixx="1.385792000000000e-05" ixy="0.0" ixz="-2.17264e-06" iyy="1.183208e-05" iyz="0.0" izz="5.19672e-06"/>
    </inertial>
  </link>
  <link name="robotiq_85_right_finger_link">
    <visual>
      <geometry>
        <mesh filename="package://robotiq_description/meshes/visual/right_finger.dae"/>
      </geometry>
    </visual>
    <collision>
      <geometry>
        <mesh filename="package://robotiq_description/meshes/collision/right_finger.stl"/>
      </geometry>
    </collision>
    <inertial>
      <origin rpy="0 0 0" xyz="-0.00346899 -5.53e-06 0.01867121"/>
      <mass value="4.260376752000000e-02"/>
      <inertia ixx="1.385792e-05" ixy="0.0" ixz="2.17264e-06" iyy="1.183208e-05" iyz="0.0" izz="5.19672e-06"/>
    </inertial>
  </link>
  <link name="robotiq_85_left_inner_knuckle_link">
    <visual>
      <geometry>
        <mesh filename="package://robotiq_description/meshes/visual/left_inner_knuckle.dae"/>
      </geometry>
    </visual>
    <collision>
      <geometry>
        <mesh filename="package://robotiq_description/meshes/collision/left_inner_knuckle.stl"/>
      </geometry>
    </collision>
    <inertial>
      <origin rpy="0 0 0" xyz="0.01897699 0.00015001 0.02247101"/>
      <mass value="2.969376448e-02"/>
      <inertia ixx="9.57136e-06" ixy="0.0" ixz="-3.93424e-06" iyy="8.69056e-06" iyz="0.0" izz="8.19144e-06"/>
    </inertial>
  </link>
  <link name="robotiq_85_right_inner_knuckle_link">
    <visual>
      <geometry>
        <mesh filename="package://robotiq_description/meshes/visual/right_inner_knuckle.dae"/>
      </geometry>
    </visual>
    <collision>
      <geometry>
        <mesh filename="package://robotiq_description/meshes/collision/right_inner_knuckle.stl"/>
      </geometry>
    </collision>
    <inertial>
      <origin rpy="0 0 0" xyz="-0.01926824 5.001e-05 0.02222178"/>
      <mass value="2.969376448e-02"/>
      <inertia ixx="9.42456e-06" ixy="0.0" ixz="3.9636e-06" iyy="8.69056e-06" iyz="0.0" izz="8.33824e-06"/>
    </inertial>
  </link>
  <link name="robotiq_85_left_finger_tip_link">
    <visual>
      <geometry>
        <mesh filename="package://robotiq_description/meshes/visual/left_finger_tip.dae"/>
      </geometry>
    </visual>
    <collision>
      <geometry>
        <mesh filename="package://robotiq_description/meshes/collision/left_finger_tip.stl"/>
      </geometry>
    </collision>
    <inertial>
      <origin rpy="0 0 0" xyz="-0.01456706 -0.0008 0.01649701"/>
      <mass value="4.268588744e-02"/>
      <inertia ixx="1.048152e-05" ixy="0.0" ixz="3.5232e-6" iyy="1.197888e-05" iyz="0.0" izz="4.22784e-06"/>
    </inertial>
  </link>
  <link name="robotiq_85_right_finger_tip_link">
    <visual>
      <geometry>
        <mesh filename="package://robotiq_description/meshes/visual/right_finger_tip.dae"/>
      </geometry>
    </visual>
    <collision>
      <geometry>
        <mesh filename="package://robotiq_description/meshes/collision/right_finger_tip.stl"/>
      </geometry>
    </collision>
    <inertial>
      <origin rpy="0 0 0" xyz="0.01456706 5e-05 0.01649701"/>
      <mass value="4.268588744e-02"/>
      <inertia ixx="1.048152e-05" ixy="0.0" ixz="-3.5232e-06" iyy="1.197888e-05" iyz="0.0" izz="4.22784e-06"/>
    </inertial>
  </link>
  <joint name="robotiq_85_base_joint" type="fixed">
    <parent link="tool_frame"/>
    <child link="robotiq_85_base_link"/>
    <origin rpy="0 0 0" xyz="0 0 0"/>
  </joint>
  <joint name="robotiq_85_left_knuckle_joint" type="revolute">
    <parent link="robotiq_85_base_link"/>
    <child link="robotiq_85_left_knuckle_link"/>
    <axis xyz="0 -1 0"/>
    <origin rpy="0 0 0" xyz="0.03060114 0.0 0.05490452"/>
    <limit effort="50" lower="0.0" upper="0.8" velocity="0.5"/>
  </joint>
  <joint name="robotiq_85_right_knuckle_joint" type="revolute">
    <parent link="robotiq_85_base_link"/>
    <child link="robotiq_85_right_knuckle_link"/>
    <axis xyz="0 -1 0"/>
    <origin rpy="0 0 0" xyz="-0.03060114 0.0 0.05490452"/>
    <limit effort="50" lower="-0.8" upper="0.0" velocity="0.5"/>
    <mimic joint="robotiq_85_left_knuckle_joint" multiplier="-1"/>
  </joint>
  <joint name="robotiq_85_left_finger_joint" type="fixed">
    <parent link="robotiq_85_left_knuckle_link"/>
    <child link="robotiq_85_left_finger_link"/>
    <origin rpy="0 0 0" xyz="0.03152616 0.0 -0.00376347"/>
  </joint>
  <joint name="robotiq_85_right_finger_joint" type="fixed">
    <parent link="robotiq_85_right_knuckle_link"/>
    <child link="robotiq_85_right_finger_link"/>
    <origin rpy="0 0 0" xyz="-0.03152616 0.0 -0.00376347"/>
  </joint>
  <joint name="robotiq_85_left_inner_knuckle_joint" type="continuous">
    <parent link="robotiq_85_base_link"/>
    <child link="robotiq_85_left_inner_knuckle_link"/>
    <axis xyz="0 -1 0"/>
    <origin rpy="0 0 0" xyz="0.0127 0.0 0.06142"/>
    <mimic joint="robotiq_85_left_knuckle_joint"/>
  </joint>
  <joint name="robotiq_85_right_inner_knuckle_joint" type="continuous">
    <parent link="robotiq_85_base_link"/>
    <child link="robotiq_85_right_inner_knuckle_link"/>
    <axis xyz="0 -1 0"/>
    <origin rpy="0 0 0" xyz="-0.0127 0.0 0.06142"/>
    <mimic joint="robotiq_85_left_knuckle_joint" multiplier="-1"/>
  </joint>
  <joint name="robotiq_85_left_finger_tip_joint" type="continuous">
    <parent link="robotiq_85_left_finger_link"/>
    <child link="robotiq_85_left_finger_tip_link"/>
    <axis xyz="0 -1 0"/>
    <origin rpy="0 0 0" xyz="0.00563134 0.0 0.04718515"/>
    <mimic joint="robotiq_85_left_knuckle_joint" multiplier="-1"/>
  </joint>
  <joint name="robotiq_85_right_finger_tip_joint" type="continuous">
    <parent link="robotiq_85_right_finger_link"/>
    <child link="robotiq_85_right_finger_tip_link"/>
    <axis xyz="0 -1 0"/>
    <origin rpy="0 0 0" xyz="-0.00563134 0.0 0.04718515"/>
    <mimic joint="robotiq_85_left_knuckle_joint"/>
  </joint>
  <link name="grasp_link"/>
  <joint name="grasp_joint" type="fixed">
    <parent link="tool_frame"/>
    <child link="grasp_link"/>
    <origin rpy="0 0 0" xyz="0 0 0.14"/>
  </joint>
</robot>
